Traceback (most recent call last):
  File "/home/codespace/.cache/pypoetry/virtualenvs/data-expressions-XOHyUNvQ-py3.10/lib/python3.10/site-packages/jupyter_cache/executors/utils.py", line 58, in single_nb_execution
    executenb(
  File "/home/codespace/.cache/pypoetry/virtualenvs/data-expressions-XOHyUNvQ-py3.10/lib/python3.10/site-packages/nbclient/client.py", line 1305, in execute
    return NotebookClient(nb=nb, resources=resources, km=km, **kwargs).execute()
  File "/home/codespace/.cache/pypoetry/virtualenvs/data-expressions-XOHyUNvQ-py3.10/lib/python3.10/site-packages/jupyter_core/utils/__init__.py", line 166, in wrapped
    return loop.run_until_complete(inner)
  File "/home/codespace/.python/current/lib/python3.10/asyncio/base_events.py", line 649, in run_until_complete
    return future.result()
  File "/home/codespace/.cache/pypoetry/virtualenvs/data-expressions-XOHyUNvQ-py3.10/lib/python3.10/site-packages/nbclient/client.py", line 705, in async_execute
    await self.async_execute_cell(
  File "/home/codespace/.cache/pypoetry/virtualenvs/data-expressions-XOHyUNvQ-py3.10/lib/python3.10/site-packages/nbclient/client.py", line 1058, in async_execute_cell
    await self._check_raise_for_error(cell, cell_index, exec_reply)
  File "/home/codespace/.cache/pypoetry/virtualenvs/data-expressions-XOHyUNvQ-py3.10/lib/python3.10/site-packages/nbclient/client.py", line 914, in _check_raise_for_error
    raise CellExecutionError.from_cell_and_msg(cell, exec_reply_content)
nbclient.exceptions.CellExecutionError: An error occurred while executing the following cell:
------------------
pl.from_pandas(data.list_datasets())
------------------


[0;31m---------------------------------------------------------------------------[0m
[0;31mTypeError[0m                                 Traceback (most recent call last)
Cell [0;32mIn[54], line 1[0m
[0;32m----> 1[0m [43mpl[49m[38;5;241;43m.[39;49m[43mfrom_pandas[49m[43m([49m[43mdata[49m[38;5;241;43m.[39;49m[43mlist_datasets[49m[43m([49m[43m)[49m[43m)[49m

File [0;32m~/.cache/pypoetry/virtualenvs/data-expressions-XOHyUNvQ-py3.10/lib/python3.10/site-packages/polars/convert.py:730[0m, in [0;36mfrom_pandas[0;34m(data, schema_overrides, rechunk, nan_to_null, include_index)[0m
[1;32m    722[0m     [38;5;28;01mreturn[39;00m pl[38;5;241m.[39mDataFrame[38;5;241m.[39m_from_pandas(
[1;32m    723[0m         data,
[1;32m    724[0m         rechunk[38;5;241m=[39mrechunk,
[0;32m   (...)[0m
[1;32m    727[0m         include_index[38;5;241m=[39minclude_index,
[1;32m    728[0m     )
[1;32m    729[0m [38;5;28;01melse[39;00m:
[0;32m--> 730[0m     [38;5;28;01mraise[39;00m [38;5;167;01mTypeError[39;00m(
[1;32m    731[0m         [38;5;124mf[39m[38;5;124m"[39m[38;5;124mexpected pandas DataFrame or Series, got [39m[38;5;132;01m{[39;00m[38;5;28mtype[39m(data)[38;5;241m.[39m[38;5;18m__name__[39m[38;5;132;01m!r}[39;00m[38;5;124m"[39m
[1;32m    732[0m     )

[0;31mTypeError[0m: expected pandas DataFrame or Series, got 'list'

