Traceback (most recent call last):
  File "/home/codespace/.cache/pypoetry/virtualenvs/data-expressions-XOHyUNvQ-py3.10/lib/python3.10/site-packages/jupyter_cache/executors/utils.py", line 58, in single_nb_execution
    executenb(
  File "/home/codespace/.cache/pypoetry/virtualenvs/data-expressions-XOHyUNvQ-py3.10/lib/python3.10/site-packages/nbclient/client.py", line 1305, in execute
    return NotebookClient(nb=nb, resources=resources, km=km, **kwargs).execute()
  File "/home/codespace/.cache/pypoetry/virtualenvs/data-expressions-XOHyUNvQ-py3.10/lib/python3.10/site-packages/jupyter_core/utils/__init__.py", line 166, in wrapped
    return loop.run_until_complete(inner)
  File "/home/codespace/.python/current/lib/python3.10/asyncio/base_events.py", line 649, in run_until_complete
    return future.result()
  File "/home/codespace/.cache/pypoetry/virtualenvs/data-expressions-XOHyUNvQ-py3.10/lib/python3.10/site-packages/nbclient/client.py", line 705, in async_execute
    await self.async_execute_cell(
  File "/home/codespace/.cache/pypoetry/virtualenvs/data-expressions-XOHyUNvQ-py3.10/lib/python3.10/site-packages/nbclient/client.py", line 1058, in async_execute_cell
    await self._check_raise_for_error(cell, cell_index, exec_reply)
  File "/home/codespace/.cache/pypoetry/virtualenvs/data-expressions-XOHyUNvQ-py3.10/lib/python3.10/site-packages/nbclient/client.py", line 914, in _check_raise_for_error
    raise CellExecutionError.from_cell_and_msg(cell, exec_reply_content)
nbclient.exceptions.CellExecutionError: An error occurred while executing the following cell:
------------------
df = pl.read_csv(source)
------------------


[0;31m---------------------------------------------------------------------------[0m
[0;31mNameError[0m                                 Traceback (most recent call last)
Cell [0;32mIn[2], line 1[0m
[0;32m----> 1[0m df [38;5;241m=[39m pl[38;5;241m.[39mread_csv([43msource[49m)

[0;31mNameError[0m: name 'source' is not defined

